ERROR 2020-07-22 16:11:04,517 log 13320 14300 Internal Server Error: /
Traceback (most recent call last):
  File "F:\PersonalStudy\Python\bglb_blog\venv\lib\site-packages\django\db\backends\utils.py", line 84, in _execute
    return self.cursor.execute(sql, params)
  File "F:\PersonalStudy\Python\bglb_blog\venv\lib\site-packages\django\db\backends\sqlite3\base.py", line 383, in execute
    return Database.Cursor.execute(self, query, params)
sqlite3.OperationalError: no such table: blog_blogpost

The above exception was the direct cause of the following exception:

Traceback (most recent call last):
  File "F:\PersonalStudy\Python\bglb_blog\venv\lib\site-packages\django\core\handlers\exception.py", line 34, in inner
    response = get_response(request)
  File "F:\PersonalStudy\Python\bglb_blog\venv\lib\site-packages\django\core\handlers\base.py", line 115, in _get_response
    response = self.process_exception_by_middleware(e, request)
  File "F:\PersonalStudy\Python\bglb_blog\venv\lib\site-packages\django\core\handlers\base.py", line 113, in _get_response
    response = wrapped_callback(request, *callback_args, **callback_kwargs)
  File "F:\PersonalStudy\专业项目\bglb_blog\blog\views.py", line 36, in blog_list
    blog_list = paginator.get_page(page)
  File "F:\PersonalStudy\Python\bglb_blog\venv\lib\site-packages\django\core\paginator.py", line 66, in get_page
    return self.page(number)
  File "F:\PersonalStudy\Python\bglb_blog\venv\lib\site-packages\django\core\paginator.py", line 70, in page
    number = self.validate_number(number)
  File "F:\PersonalStudy\Python\bglb_blog\venv\lib\site-packages\django\core\paginator.py", line 48, in validate_number
    if number > self.num_pages:
  File "F:\PersonalStudy\Python\bglb_blog\venv\lib\site-packages\django\utils\functional.py", line 80, in __get__
    res = instance.__dict__[self.name] = self.func(instance)
  File "F:\PersonalStudy\Python\bglb_blog\venv\lib\site-packages\django\core\paginator.py", line 97, in num_pages
    if self.count == 0 and not self.allow_empty_first_page:
  File "F:\PersonalStudy\Python\bglb_blog\venv\lib\site-packages\django\utils\functional.py", line 80, in __get__
    res = instance.__dict__[self.name] = self.func(instance)
  File "F:\PersonalStudy\Python\bglb_blog\venv\lib\site-packages\django\core\paginator.py", line 91, in count
    return c()
  File "F:\PersonalStudy\Python\bglb_blog\venv\lib\site-packages\django\db\models\query.py", line 392, in count
    return self.query.get_count(using=self.db)
  File "F:\PersonalStudy\Python\bglb_blog\venv\lib\site-packages\django\db\models\sql\query.py", line 504, in get_count
    number = obj.get_aggregation(using, ['__count'])['__count']
  File "F:\PersonalStudy\Python\bglb_blog\venv\lib\site-packages\django\db\models\sql\query.py", line 489, in get_aggregation
    result = compiler.execute_sql(SINGLE)
  File "F:\PersonalStudy\Python\bglb_blog\venv\lib\site-packages\django\db\models\sql\compiler.py", line 1140, in execute_sql
    cursor.execute(sql, params)
  File "F:\PersonalStudy\Python\bglb_blog\venv\lib\site-packages\django\db\backends\utils.py", line 99, in execute
    return super().execute(sql, params)
  File "F:\PersonalStudy\Python\bglb_blog\venv\lib\site-packages\django\db\backends\utils.py", line 67, in execute
    return self._execute_with_wrappers(sql, params, many=False, executor=self._execute)
  File "F:\PersonalStudy\Python\bglb_blog\venv\lib\site-packages\django\db\backends\utils.py", line 76, in _execute_with_wrappers
    return executor(sql, params, many, context)
  File "F:\PersonalStudy\Python\bglb_blog\venv\lib\site-packages\django\db\backends\utils.py", line 84, in _execute
    return self.cursor.execute(sql, params)
  File "F:\PersonalStudy\Python\bglb_blog\venv\lib\site-packages\django\db\utils.py", line 89, in __exit__
    raise dj_exc_value.with_traceback(traceback) from exc_value
  File "F:\PersonalStudy\Python\bglb_blog\venv\lib\site-packages\django\db\backends\utils.py", line 84, in _execute
    return self.cursor.execute(sql, params)
  File "F:\PersonalStudy\Python\bglb_blog\venv\lib\site-packages\django\db\backends\sqlite3\base.py", line 383, in execute
    return Database.Cursor.execute(self, query, params)
django.db.utils.OperationalError: no such table: blog_blogpost
ERROR 2020-07-22 16:11:06,226 basehttp 13320 14300 "GET / HTTP/1.1" 500 161363
WARNING 2020-07-22 16:11:06,591 log 13320 14300 Not Found: /favicon.ico
WARNING 2020-07-22 16:11:06,591 basehttp 13320 14300 "GET /favicon.ico HTTP/1.1" 404 2870
ERROR 2020-07-22 16:12:50,022 log 4000 2884 Internal Server Error: /
Traceback (most recent call last):
  File "F:\PersonalStudy\Python\bglb_blog\venv\lib\site-packages\django\db\backends\utils.py", line 84, in _execute
    return self.cursor.execute(sql, params)
  File "F:\PersonalStudy\Python\bglb_blog\venv\lib\site-packages\django\db\backends\sqlite3\base.py", line 383, in execute
    return Database.Cursor.execute(self, query, params)
sqlite3.OperationalError: no such table: blog_blogpost

The above exception was the direct cause of the following exception:

Traceback (most recent call last):
  File "F:\PersonalStudy\Python\bglb_blog\venv\lib\site-packages\django\core\handlers\exception.py", line 34, in inner
    response = get_response(request)
  File "F:\PersonalStudy\Python\bglb_blog\venv\lib\site-packages\django\core\handlers\base.py", line 115, in _get_response
    response = self.process_exception_by_middleware(e, request)
  File "F:\PersonalStudy\Python\bglb_blog\venv\lib\site-packages\django\core\handlers\base.py", line 113, in _get_response
    response = wrapped_callback(request, *callback_args, **callback_kwargs)
  File "F:\PersonalStudy\专业项目\bglb_blog\blog\views.py", line 36, in blog_list
    blog_list = paginator.get_page(page)
  File "F:\PersonalStudy\Python\bglb_blog\venv\lib\site-packages\django\core\paginator.py", line 66, in get_page
    return self.page(number)
  File "F:\PersonalStudy\Python\bglb_blog\venv\lib\site-packages\django\core\paginator.py", line 70, in page
    number = self.validate_number(number)
  File "F:\PersonalStudy\Python\bglb_blog\venv\lib\site-packages\django\core\paginator.py", line 48, in validate_number
    if number > self.num_pages:
  File "F:\PersonalStudy\Python\bglb_blog\venv\lib\site-packages\django\utils\functional.py", line 80, in __get__
    res = instance.__dict__[self.name] = self.func(instance)
  File "F:\PersonalStudy\Python\bglb_blog\venv\lib\site-packages\django\core\paginator.py", line 97, in num_pages
    if self.count == 0 and not self.allow_empty_first_page:
  File "F:\PersonalStudy\Python\bglb_blog\venv\lib\site-packages\django\utils\functional.py", line 80, in __get__
    res = instance.__dict__[self.name] = self.func(instance)
  File "F:\PersonalStudy\Python\bglb_blog\venv\lib\site-packages\django\core\paginator.py", line 91, in count
    return c()
  File "F:\PersonalStudy\Python\bglb_blog\venv\lib\site-packages\django\db\models\query.py", line 392, in count
    return self.query.get_count(using=self.db)
  File "F:\PersonalStudy\Python\bglb_blog\venv\lib\site-packages\django\db\models\sql\query.py", line 504, in get_count
    number = obj.get_aggregation(using, ['__count'])['__count']
  File "F:\PersonalStudy\Python\bglb_blog\venv\lib\site-packages\django\db\models\sql\query.py", line 489, in get_aggregation
    result = compiler.execute_sql(SINGLE)
  File "F:\PersonalStudy\Python\bglb_blog\venv\lib\site-packages\django\db\models\sql\compiler.py", line 1140, in execute_sql
    cursor.execute(sql, params)
  File "F:\PersonalStudy\Python\bglb_blog\venv\lib\site-packages\django\db\backends\utils.py", line 99, in execute
    return super().execute(sql, params)
  File "F:\PersonalStudy\Python\bglb_blog\venv\lib\site-packages\django\db\backends\utils.py", line 67, in execute
    return self._execute_with_wrappers(sql, params, many=False, executor=self._execute)
  File "F:\PersonalStudy\Python\bglb_blog\venv\lib\site-packages\django\db\backends\utils.py", line 76, in _execute_with_wrappers
    return executor(sql, params, many, context)
  File "F:\PersonalStudy\Python\bglb_blog\venv\lib\site-packages\django\db\backends\utils.py", line 84, in _execute
    return self.cursor.execute(sql, params)
  File "F:\PersonalStudy\Python\bglb_blog\venv\lib\site-packages\django\db\utils.py", line 89, in __exit__
    raise dj_exc_value.with_traceback(traceback) from exc_value
  File "F:\PersonalStudy\Python\bglb_blog\venv\lib\site-packages\django\db\backends\utils.py", line 84, in _execute
    return self.cursor.execute(sql, params)
  File "F:\PersonalStudy\Python\bglb_blog\venv\lib\site-packages\django\db\backends\sqlite3\base.py", line 383, in execute
    return Database.Cursor.execute(self, query, params)
django.db.utils.OperationalError: no such table: blog_blogpost
ERROR 2020-07-22 16:12:51,499 basehttp 4000 2884 "GET / HTTP/1.1" 500 161409
WARNING 2020-07-22 16:12:51,712 log 4000 2884 Not Found: /favicon.ico
WARNING 2020-07-22 16:12:51,712 basehttp 4000 2884 "GET /favicon.ico HTTP/1.1" 404 2870
WARNING 2020-07-22 16:13:26,920 basehttp 4000 1592 "GET /static/js/login.min.js HTTP/1.1" 404 1669
WARNING 2020-07-22 16:15:08,241 log 4000 4560 Not Found: /admin
WARNING 2020-07-22 16:15:08,243 basehttp 4000 4560 "GET /admin HTTP/1.1" 404 2852
WARNING 2020-07-22 16:15:08,273 log 4000 4560 Not Found: /favicon.ico
WARNING 2020-07-22 16:15:08,273 basehttp 4000 4560 "GET /favicon.ico HTTP/1.1" 404 2870
ERROR 2020-07-22 16:29:05,829 log 4000 10444 Internal Server Error: /blog/blog-upimage/
Traceback (most recent call last):
  File "F:\PersonalStudy\Python\bglb_blog\venv\lib\site-packages\urllib3\connection.py", line 160, in _new_conn
    (self._dns_host, self.port), self.timeout, **extra_kw
  File "F:\PersonalStudy\Python\bglb_blog\venv\lib\site-packages\urllib3\util\connection.py", line 84, in create_connection
    raise err
  File "F:\PersonalStudy\Python\bglb_blog\venv\lib\site-packages\urllib3\util\connection.py", line 74, in create_connection
    sock.connect(sa)
TimeoutError: [WinError 10060] 由于连接方在一段时间后没有正确答复或连接的主机没有反应，连接尝试失败。

During handling of the above exception, another exception occurred:

Traceback (most recent call last):
  File "F:\PersonalStudy\Python\bglb_blog\venv\lib\site-packages\urllib3\connectionpool.py", line 677, in urlopen
    chunked=chunked,
  File "F:\PersonalStudy\Python\bglb_blog\venv\lib\site-packages\urllib3\connectionpool.py", line 381, in _make_request
    self._validate_conn(conn)
  File "F:\PersonalStudy\Python\bglb_blog\venv\lib\site-packages\urllib3\connectionpool.py", line 976, in _validate_conn
    conn.connect()
  File "F:\PersonalStudy\Python\bglb_blog\venv\lib\site-packages\urllib3\connection.py", line 308, in connect
    conn = self._new_conn()
  File "F:\PersonalStudy\Python\bglb_blog\venv\lib\site-packages\urllib3\connection.py", line 172, in _new_conn
    self, "Failed to establish a new connection: %s" % e
urllib3.exceptions.NewConnectionError: <urllib3.connection.HTTPSConnection object at 0x0000020C59C5BE80>: Failed to establish a new connection: [WinError 10060] 由于连接方在一段时间后没有正确答复或连接的主机没有反应，连接尝试失败。

During handling of the above exception, another exception occurred:

Traceback (most recent call last):
  File "F:\PersonalStudy\Python\bglb_blog\venv\lib\site-packages\requests\adapters.py", line 449, in send
    timeout=timeout
  File "F:\PersonalStudy\Python\bglb_blog\venv\lib\site-packages\urllib3\connectionpool.py", line 725, in urlopen
    method, url, error=e, _pool=self, _stacktrace=sys.exc_info()[2]
  File "F:\PersonalStudy\Python\bglb_blog\venv\lib\site-packages\urllib3\util\retry.py", line 439, in increment
    raise MaxRetryError(_pool, url, error or ResponseError(cause))
urllib3.exceptions.MaxRetryError: HTTPSConnectionPool(host='bglb-blog.oss-cn-beijing-internal.aliyuncs.com', port=443): Max retries exceeded with url: /img%2F1595406461166.png (Caused by NewConnectionError('<urllib3.connection.HTTPSConnection object at 0x0000020C59C5BE80>: Failed to establish a new connection: [WinError 10060] 由于连接方在一段时间后没有正确答复或连接的主机没有反应，连接尝试失败。',))

During handling of the above exception, another exception occurred:

Traceback (most recent call last):
  File "F:\PersonalStudy\Python\bglb_blog\venv\lib\site-packages\oss2\http.py", line 48, in do_request
    timeout=timeout))
  File "F:\PersonalStudy\Python\bglb_blog\venv\lib\site-packages\requests\sessions.py", line 530, in request
    resp = self.send(prep, **send_kwargs)
  File "F:\PersonalStudy\Python\bglb_blog\venv\lib\site-packages\requests\sessions.py", line 643, in send
    r = adapter.send(request, **kwargs)
  File "F:\PersonalStudy\Python\bglb_blog\venv\lib\site-packages\requests\adapters.py", line 516, in send
    raise ConnectionError(e, request=request)
requests.exceptions.ConnectionError: HTTPSConnectionPool(host='bglb-blog.oss-cn-beijing-internal.aliyuncs.com', port=443): Max retries exceeded with url: /img%2F1595406461166.png (Caused by NewConnectionError('<urllib3.connection.HTTPSConnection object at 0x0000020C59C5BE80>: Failed to establish a new connection: [WinError 10060] 由于连接方在一段时间后没有正确答复或连接的主机没有反应，连接尝试失败。',))

During handling of the above exception, another exception occurred:

Traceback (most recent call last):
  File "F:\PersonalStudy\Python\bglb_blog\venv\lib\site-packages\django\core\handlers\exception.py", line 34, in inner
    response = get_response(request)
  File "F:\PersonalStudy\Python\bglb_blog\venv\lib\site-packages\django\core\handlers\base.py", line 115, in _get_response
    response = self.process_exception_by_middleware(e, request)
  File "F:\PersonalStudy\Python\bglb_blog\venv\lib\site-packages\django\core\handlers\base.py", line 113, in _get_response
    response = wrapped_callback(request, *callback_args, **callback_kwargs)
  File "F:\PersonalStudy\专业项目\bglb_blog\blog\views.py", line 132, in blog_image
    img_url = update_img_file(img)
  File "F:\PersonalStudy\专业项目\bglb_blog\blog\utils.py", line 22, in update_img_file
    res = bucket.put_object(base_img_name, image)
  File "F:\PersonalStudy\Python\bglb_blog\venv\lib\site-packages\oss2\api.py", line 552, in put_object
    resp = self.__do_object('PUT', key, data=data, headers=headers)
  File "F:\PersonalStudy\Python\bglb_blog\venv\lib\site-packages\oss2\api.py", line 2348, in __do_object
    return self._do(method, self.bucket_name, key, **kwargs)
  File "F:\PersonalStudy\Python\bglb_blog\venv\lib\site-packages\oss2\api.py", line 223, in _do
    resp = self.session.do_request(req, timeout=self.timeout)
  File "F:\PersonalStudy\Python\bglb_blog\venv\lib\site-packages\oss2\http.py", line 50, in do_request
    raise RequestError(e)
oss2.exceptions.RequestError: {'status': -2, 'x-oss-request-id': '', 'details': "RequestError: HTTPSConnectionPool(host='bglb-blog.oss-cn-beijing-internal.aliyuncs.com', port=443): Max retries exceeded with url: /img%2F1595406461166.png (Caused by NewConnectionError('<urllib3.connection.HTTPSConnection object at 0x0000020C59C5BE80>: Failed to establish a new connection: [WinError 10060] 由于连接方在一段时间后没有正确答复或连接的主机没有反应，连接尝试失败。',))"}
ERROR 2020-07-22 16:29:06,310 basehttp 4000 10444 "POST /blog/blog-upimage/ HTTP/1.1" 500 25604
ERROR 2020-07-22 16:30:01,553 log 4000 13328 Internal Server Error: /blog/blog-upimage/
Traceback (most recent call last):
  File "F:\PersonalStudy\Python\bglb_blog\venv\lib\site-packages\urllib3\connection.py", line 160, in _new_conn
    (self._dns_host, self.port), self.timeout, **extra_kw
  File "F:\PersonalStudy\Python\bglb_blog\venv\lib\site-packages\urllib3\util\connection.py", line 84, in create_connection
    raise err
  File "F:\PersonalStudy\Python\bglb_blog\venv\lib\site-packages\urllib3\util\connection.py", line 74, in create_connection
    sock.connect(sa)
TimeoutError: [WinError 10060] 由于连接方在一段时间后没有正确答复或连接的主机没有反应，连接尝试失败。

During handling of the above exception, another exception occurred:

Traceback (most recent call last):
  File "F:\PersonalStudy\Python\bglb_blog\venv\lib\site-packages\urllib3\connectionpool.py", line 677, in urlopen
    chunked=chunked,
  File "F:\PersonalStudy\Python\bglb_blog\venv\lib\site-packages\urllib3\connectionpool.py", line 381, in _make_request
    self._validate_conn(conn)
  File "F:\PersonalStudy\Python\bglb_blog\venv\lib\site-packages\urllib3\connectionpool.py", line 976, in _validate_conn
    conn.connect()
  File "F:\PersonalStudy\Python\bglb_blog\venv\lib\site-packages\urllib3\connection.py", line 308, in connect
    conn = self._new_conn()
  File "F:\PersonalStudy\Python\bglb_blog\venv\lib\site-packages\urllib3\connection.py", line 172, in _new_conn
    self, "Failed to establish a new connection: %s" % e
urllib3.exceptions.NewConnectionError: <urllib3.connection.HTTPSConnection object at 0x0000020C5A0826A0>: Failed to establish a new connection: [WinError 10060] 由于连接方在一段时间后没有正确答复或连接的主机没有反应，连接尝试失败。

During handling of the above exception, another exception occurred:

Traceback (most recent call last):
  File "F:\PersonalStudy\Python\bglb_blog\venv\lib\site-packages\requests\adapters.py", line 449, in send
    timeout=timeout
  File "F:\PersonalStudy\Python\bglb_blog\venv\lib\site-packages\urllib3\connectionpool.py", line 725, in urlopen
    method, url, error=e, _pool=self, _stacktrace=sys.exc_info()[2]
  File "F:\PersonalStudy\Python\bglb_blog\venv\lib\site-packages\urllib3\util\retry.py", line 439, in increment
    raise MaxRetryError(_pool, url, error or ResponseError(cause))
urllib3.exceptions.MaxRetryError: HTTPSConnectionPool(host='bglb-blog.oss-cn-beijing-internal.aliyuncs.com', port=443): Max retries exceeded with url: /img%2F1595406517377.png (Caused by NewConnectionError('<urllib3.connection.HTTPSConnection object at 0x0000020C5A0826A0>: Failed to establish a new connection: [WinError 10060] 由于连接方在一段时间后没有正确答复或连接的主机没有反应，连接尝试失败。',))

During handling of the above exception, another exception occurred:

Traceback (most recent call last):
  File "F:\PersonalStudy\Python\bglb_blog\venv\lib\site-packages\oss2\http.py", line 48, in do_request
    timeout=timeout))
  File "F:\PersonalStudy\Python\bglb_blog\venv\lib\site-packages\requests\sessions.py", line 530, in request
    resp = self.send(prep, **send_kwargs)
  File "F:\PersonalStudy\Python\bglb_blog\venv\lib\site-packages\requests\sessions.py", line 643, in send
    r = adapter.send(request, **kwargs)
  File "F:\PersonalStudy\Python\bglb_blog\venv\lib\site-packages\requests\adapters.py", line 516, in send
    raise ConnectionError(e, request=request)
requests.exceptions.ConnectionError: HTTPSConnectionPool(host='bglb-blog.oss-cn-beijing-internal.aliyuncs.com', port=443): Max retries exceeded with url: /img%2F1595406517377.png (Caused by NewConnectionError('<urllib3.connection.HTTPSConnection object at 0x0000020C5A0826A0>: Failed to establish a new connection: [WinError 10060] 由于连接方在一段时间后没有正确答复或连接的主机没有反应，连接尝试失败。',))

During handling of the above exception, another exception occurred:

Traceback (most recent call last):
  File "F:\PersonalStudy\Python\bglb_blog\venv\lib\site-packages\django\core\handlers\exception.py", line 34, in inner
    response = get_response(request)
  File "F:\PersonalStudy\Python\bglb_blog\venv\lib\site-packages\django\core\handlers\base.py", line 115, in _get_response
    response = self.process_exception_by_middleware(e, request)
  File "F:\PersonalStudy\Python\bglb_blog\venv\lib\site-packages\django\core\handlers\base.py", line 113, in _get_response
    response = wrapped_callback(request, *callback_args, **callback_kwargs)
  File "F:\PersonalStudy\专业项目\bglb_blog\blog\views.py", line 132, in blog_image
    img_url = update_img_file(img)
  File "F:\PersonalStudy\专业项目\bglb_blog\blog\utils.py", line 22, in update_img_file
    res = bucket.put_object(base_img_name, image)
  File "F:\PersonalStudy\Python\bglb_blog\venv\lib\site-packages\oss2\api.py", line 552, in put_object
    resp = self.__do_object('PUT', key, data=data, headers=headers)
  File "F:\PersonalStudy\Python\bglb_blog\venv\lib\site-packages\oss2\api.py", line 2348, in __do_object
    return self._do(method, self.bucket_name, key, **kwargs)
  File "F:\PersonalStudy\Python\bglb_blog\venv\lib\site-packages\oss2\api.py", line 223, in _do
    resp = self.session.do_request(req, timeout=self.timeout)
  File "F:\PersonalStudy\Python\bglb_blog\venv\lib\site-packages\oss2\http.py", line 50, in do_request
    raise RequestError(e)
oss2.exceptions.RequestError: {'status': -2, 'x-oss-request-id': '', 'details': "RequestError: HTTPSConnectionPool(host='bglb-blog.oss-cn-beijing-internal.aliyuncs.com', port=443): Max retries exceeded with url: /img%2F1595406517377.png (Caused by NewConnectionError('<urllib3.connection.HTTPSConnection object at 0x0000020C5A0826A0>: Failed to establish a new connection: [WinError 10060] 由于连接方在一段时间后没有正确答复或连接的主机没有反应，连接尝试失败。',))"}
ERROR 2020-07-22 16:30:01,979 basehttp 4000 13328 "POST /blog/blog-upimage/ HTTP/1.1" 500 25603
ERROR 2020-07-22 16:34:43,761 log 10504 8868 Internal Server Error: /blog/blog-upimage/
Traceback (most recent call last):
  File "F:\PersonalStudy\Python\bglb_blog\venv\lib\site-packages\urllib3\connection.py", line 160, in _new_conn
    (self._dns_host, self.port), self.timeout, **extra_kw
  File "F:\PersonalStudy\Python\bglb_blog\venv\lib\site-packages\urllib3\util\connection.py", line 84, in create_connection
    raise err
  File "F:\PersonalStudy\Python\bglb_blog\venv\lib\site-packages\urllib3\util\connection.py", line 74, in create_connection
    sock.connect(sa)
TimeoutError: [WinError 10060] 由于连接方在一段时间后没有正确答复或连接的主机没有反应，连接尝试失败。

During handling of the above exception, another exception occurred:

Traceback (most recent call last):
  File "F:\PersonalStudy\Python\bglb_blog\venv\lib\site-packages\urllib3\connectionpool.py", line 677, in urlopen
    chunked=chunked,
  File "F:\PersonalStudy\Python\bglb_blog\venv\lib\site-packages\urllib3\connectionpool.py", line 381, in _make_request
    self._validate_conn(conn)
  File "F:\PersonalStudy\Python\bglb_blog\venv\lib\site-packages\urllib3\connectionpool.py", line 976, in _validate_conn
    conn.connect()
  File "F:\PersonalStudy\Python\bglb_blog\venv\lib\site-packages\urllib3\connection.py", line 308, in connect
    conn = self._new_conn()
  File "F:\PersonalStudy\Python\bglb_blog\venv\lib\site-packages\urllib3\connection.py", line 172, in _new_conn
    self, "Failed to establish a new connection: %s" % e
urllib3.exceptions.NewConnectionError: <urllib3.connection.HTTPSConnection object at 0x000002CED2610240>: Failed to establish a new connection: [WinError 10060] 由于连接方在一段时间后没有正确答复或连接的主机没有反应，连接尝试失败。

During handling of the above exception, another exception occurred:

Traceback (most recent call last):
  File "F:\PersonalStudy\Python\bglb_blog\venv\lib\site-packages\requests\adapters.py", line 449, in send
    timeout=timeout
  File "F:\PersonalStudy\Python\bglb_blog\venv\lib\site-packages\urllib3\connectionpool.py", line 725, in urlopen
    method, url, error=e, _pool=self, _stacktrace=sys.exc_info()[2]
  File "F:\PersonalStudy\Python\bglb_blog\venv\lib\site-packages\urllib3\util\retry.py", line 439, in increment
    raise MaxRetryError(_pool, url, error or ResponseError(cause))
urllib3.exceptions.MaxRetryError: HTTPSConnectionPool(host='bglb-blog.oss-cn-beijing-internal.aliyuncs.com', port=443): Max retries exceeded with url: /img%2F1595406778676.png (Caused by NewConnectionError('<urllib3.connection.HTTPSConnection object at 0x000002CED2610240>: Failed to establish a new connection: [WinError 10060] 由于连接方在一段时间后没有正确答复或连接的主机没有反应，连接尝试失败。',))

During handling of the above exception, another exception occurred:

Traceback (most recent call last):
  File "F:\PersonalStudy\Python\bglb_blog\venv\lib\site-packages\oss2\http.py", line 48, in do_request
    timeout=timeout))
  File "F:\PersonalStudy\Python\bglb_blog\venv\lib\site-packages\requests\sessions.py", line 530, in request
    resp = self.send(prep, **send_kwargs)
  File "F:\PersonalStudy\Python\bglb_blog\venv\lib\site-packages\requests\sessions.py", line 643, in send
    r = adapter.send(request, **kwargs)
  File "F:\PersonalStudy\Python\bglb_blog\venv\lib\site-packages\requests\adapters.py", line 516, in send
    raise ConnectionError(e, request=request)
requests.exceptions.ConnectionError: HTTPSConnectionPool(host='bglb-blog.oss-cn-beijing-internal.aliyuncs.com', port=443): Max retries exceeded with url: /img%2F1595406778676.png (Caused by NewConnectionError('<urllib3.connection.HTTPSConnection object at 0x000002CED2610240>: Failed to establish a new connection: [WinError 10060] 由于连接方在一段时间后没有正确答复或连接的主机没有反应，连接尝试失败。',))

During handling of the above exception, another exception occurred:

Traceback (most recent call last):
  File "F:\PersonalStudy\Python\bglb_blog\venv\lib\site-packages\django\core\handlers\exception.py", line 34, in inner
    response = get_response(request)
  File "F:\PersonalStudy\Python\bglb_blog\venv\lib\site-packages\django\core\handlers\base.py", line 115, in _get_response
    response = self.process_exception_by_middleware(e, request)
  File "F:\PersonalStudy\Python\bglb_blog\venv\lib\site-packages\django\core\handlers\base.py", line 113, in _get_response
    response = wrapped_callback(request, *callback_args, **callback_kwargs)
  File "F:\PersonalStudy\专业项目\bglb_blog\blog\views.py", line 132, in blog_image
    img_url = update_img_file(img)
  File "F:\PersonalStudy\专业项目\bglb_blog\blog\utils.py", line 22, in update_img_file
    res = bucket.put_object(base_img_name, image)
  File "F:\PersonalStudy\Python\bglb_blog\venv\lib\site-packages\oss2\api.py", line 552, in put_object
    resp = self.__do_object('PUT', key, data=data, headers=headers)
  File "F:\PersonalStudy\Python\bglb_blog\venv\lib\site-packages\oss2\api.py", line 2348, in __do_object
    return self._do(method, self.bucket_name, key, **kwargs)
  File "F:\PersonalStudy\Python\bglb_blog\venv\lib\site-packages\oss2\api.py", line 223, in _do
    resp = self.session.do_request(req, timeout=self.timeout)
  File "F:\PersonalStudy\Python\bglb_blog\venv\lib\site-packages\oss2\http.py", line 50, in do_request
    raise RequestError(e)
oss2.exceptions.RequestError: {'status': -2, 'x-oss-request-id': '', 'details': "RequestError: HTTPSConnectionPool(host='bglb-blog.oss-cn-beijing-internal.aliyuncs.com', port=443): Max retries exceeded with url: /img%2F1595406778676.png (Caused by NewConnectionError('<urllib3.connection.HTTPSConnection object at 0x000002CED2610240>: Failed to establish a new connection: [WinError 10060] 由于连接方在一段时间后没有正确答复或连接的主机没有反应，连接尝试失败。',))"}
ERROR 2020-07-22 16:34:45,283 basehttp 10504 8868 "POST /blog/blog-upimage/ HTTP/1.1" 500 25604
WARNING 2020-07-22 16:45:15,615 log 3088 10552 Not Found: /favicon.ico
WARNING 2020-07-22 16:45:15,616 basehttp 3088 10552 "GET /favicon.ico HTTP/1.1" 404 2870
WARNING 2020-07-22 16:51:50,921 log 3088 8108 Not Found: /favicon.ico
WARNING 2020-07-22 16:51:50,921 basehttp 3088 8108 "GET /favicon.ico HTTP/1.1" 404 2870
